#   异常处理

Java语言对异常处理的支持，包括 catch 、throw 、finally 、try-with-resources 和 throws 。

##  catch 匹配

演示使用 try/catch 捕获异常，其中 catch 只有一条，但是可以有多条，每条对应一种异常类型。

```Java
try{
    //可能触发异常的代码
} catch(NumberFormatException e){
    System.out.println("not valid number");
} catch(RuntimeException e){
    System.out.println("runtime exception "+e.getMessage());
} catch(Exception e){
    e.printStackTrace();
}
```

异常处理机制将根据抛出的异常类型找第一个匹配的 catch 块，找到后，执行 catch 块内的代码，不再执行其他 catch 块，如果没有找到，会继续到上层方法中查找。

抛出的异常类型是 catch 中声明异常的子类也算匹配，所以需要将具体的子类放在前面，如果基类 Exception 放在前面，则其他更具体的 catch 代码将得不到执行。

演示了对异常信息的利用， e.getMessage() 获取异常消息， e.printStackTrace() 打印异常栈到标准错误输出流。

如果多种异常处理的代码是类似的，在 Java SE 7 中可以这样：

```Java
try {
    //可能抛出 ExceptionA 和 ExceptionB
} catch (ExceptionA | ExceptionB e) {
    e.printStackTrace();
}
```

##  重新抛出异常

在 catch 块内处理完后，可以重新抛出异常，异常可以是原来的，也可以是新建的，如下所示：

```Java
try{
    //可能触发异常的代码
}catch(NumberFormatException e){
    System.out.println("not valid number");
    throw new AppException("输入格式不正确", e);
}catch(Exception e){
    e.printStackTrace();
    throw e;
}
```

对于 Exception，在打印出异常栈后，就通过 throw e 重新抛出了。

对于 NumberFormatException ，重新抛出了一个 AppException，当前 Exception 作为cause传递给了 AppException ，这样就形成了一个异常链，捕获到 AppException 的代码可以通过 getCause() 得到 NumberFormatException。

##  finally

异常机制中海油一个重要的部分，就是 finally。 catch 后面可以跟 finally 语句，语法如下所示：

```Java
try{
//可能抛出异常
}catch(Exception e){
//捕获异常
}finally{
//不管有无异常都执行
}
```

finally 内的代码不管有无异常发生，都会执行，具体来说：

-   如果没有异常发生，在 try 内的代码执行结束后执行
-   如果有异常发生且被 catch 捕获，在 catch 内的代码执行结束后执行
-   如果有异常发生但没被捕获，则在异常被抛给上层之前执行

由于 finally 这个特点，他一般用于释放资源，如数据库连接、文件流等。

try/catch/finally 语法中，catch 不是必需的，也可以只有 try/finally，表示不捕获异常，异常自动向上传递，但 finally 中的代码在异常发生后也执行。

一般而言，为避免混淆，应该避免在 finally 中使用 return 语句或跑出异常，如果调用的其他代码可能抛出异常，则应该捕获异常并进行处理。

##  try-with-resources

对于一些使用资源的场景，比如文件和数据库连接，典型的使用流程是首先打开资源，最后在 finally 语句中调用资源的关闭方法，针对这种场景，Java 7开始支持一些新的语法，称之为 try-with-resources，这种语法针对实现了 java.lang.AutoCloseable 接口的对象。

没有 try-with-resources 时，使用形式如下：

```Java
public static void useResource() throws Exception {
    AutoCloseable r = new FileInputStream("hello"); //创建资源
    try {
        //使用资源
    } finally {
        r.close();
    }
}
```

使用 try-with-resources 语法，形式如下：

```Java
public static void useResource() throws Exception {
    try(AutoCloseable r = new FileInputStream("hello")) { //创建资源
        //使用资源
    }
}
```

资源 r 的声明和初始化放在 try 语句内，不再调用 finally ，在语句执行完 try 语句后，会自动调用资源的 close 方法。

##  throws

异常机制中， throws 用于声明一个方法可能抛出的异常，语法如下所示：

```Java
public void test() throws AppException,SQLException, NumberFormatException {
    // 主体代码
}
```

throws 跟在方法的括号后面，可以声明多个异常，以逗号分隔。

这个声明的含义是，这个方法内可能抛出这些异常，且没有对这些异常进行处理，调用者必须进行处理。

如果一个方法内调用了另一个声明抛出受检异常的方法，则必须处理这些受检异常，处理的方式既可以是 catch，也可以是继续使用 throws，如下所示：

```Java
public void tester() throws AppException {
    try {
        test();
    } catch(SQLException e) {
        e.printStackTrace();
    }
}
```

对于 test 抛出的 SQLException，这里使用 catch，而对于 AppException ，则将其添加到了自己方法的 throws 语句中，表示当前方法处理不了，继续由上层处理。

##  对比受检和未受检异常

Java 中对于受检异常和未受检异常的区分是没有太大意义的，可以统一使用未受检异常来代替。

无论是受检异常还是未受检异常，无论是否出现在 throws 声明中，都应该在合适的地方以适当的方式进行处理，而不只是为了满足编译器的要求盲目处理异常。

其实，观点本身并不太重要，更重要的是一致性，一个项目中，应该对如何使用异常打成一致，并按照约定使用。


----